#VRML_SIM R2022b utf8

EXTERNPROTO "https://raw.githubusercontent.com/cyberbotics/webots/R2022b/projects/objects/backgrounds/protos/TexturedBackground.proto"
EXTERNPROTO "https://raw.githubusercontent.com/cyberbotics/webots/R2022b/projects/objects/backgrounds/protos/TexturedBackgroundLight.proto"
EXTERNPROTO "https://raw.githubusercontent.com/cyberbotics/webots/R2022b/projects/objects/floors/protos/RectangleArena.proto"
EXTERNPROTO "https://raw.githubusercontent.com/cyberbotics/webots/R2022b/projects/appearances/protos/BrushedAluminium.proto"
EXTERNPROTO "https://raw.githubusercontent.com/cyberbotics/webots/R2022b/projects/objects/balls/protos/FifaSoccerBall.proto"
EXTERNPROTO "https://raw.githubusercontent.com/cyberbotics/webots/R2022b/projects/objects/fruits/protos/Apple.proto"
EXTERNPROTO "https://raw.githubusercontent.com/cyberbotics/webots/R2022b/projects/objects/plants/protos/FlowerPot.proto"

WorldInfo {
  basicTimeStep 10
}
Viewpoint {
  orientation -0.19765599431601422 -0.16155092690014441 0.9668678327096483 4.4791465615308805
  position 0.21726036844493324 1.4518459417200633 0.6831896226331567
}
TexturedBackground {
}
TexturedBackgroundLight {
}
RectangleArena {
  translation -0.0119711 0.031808 -1.66533e-16
  floorTileSize 0.1 0.1
  wallHeight 0.05
}
Robot {
  children [
    Transform {
      translation 0 0 0.05
      children [
        Shape {
          appearance BrushedAluminium {
          }
          geometry Cylinder {
            height 0.1
            radius 0.05
            subdivision 38
          }
        }
      ]
    }
    Transform {
      translation 0 0 0.1
      children [
        HingeJoint {
          jointParameters HingeJointParameters {
            axis 0 0 1
          }
          device [
            RotationalMotor {
              name "pan"
            }
          ]
          endPoint Solid {
            children [
              Transform {
                translation 0 0 0.005
                children [
                  Shape {
                    appearance BrushedAluminium {
                      colorOverride 0.7 0.8 0.4
                    }
                    geometry Cylinder {
                      height 0.01
                      radius 0.05
                    }
                  }
                ]
              }
              Transform {
                translation -0.075 0 0.005
                children [
                  Shape {
                    appearance BrushedAluminium {
                      colorOverride 0.7 0.8 0.4
                    }
                    geometry Box {
                      size 0.15 0.1 0.01
                    }
                  }
                ]
              }
              Transform {
                translation -0.145 0 0.075
                children [
                  Shape {
                    appearance BrushedAluminium {
                      colorOverride 0.7 0.8 0.4
                    }
                    geometry Box {
                      size 0.01 0.1 0.15
                    }
                  }
                ]
              }
              Transform {
                translation -0.14 0 0.15
                rotation 0 1 0 1.57079655725627
                children [
                  Shape {
                    appearance BrushedAluminium {
                      colorOverride 0.7 0.8 0.4
                    }
                    geometry Cylinder {
                      height 0.02
                      radius 0.05
                    }
                  }
                ]
              }
              Transform {
                translation -0.13 0 0.15
                rotation 0 1 0 1.5707963267948968
                children [
                  HingeJoint {
                    jointParameters HingeJointParameters {
                      axis 0 0 1
                    }
                    device [
                      RotationalMotor {
                        name "tilt"
                      }
                    ]
                    endPoint Solid {
                      children [
                        Transform {
                          translation 0 0 0.005
                          children [
                            Shape {
                              appearance BrushedAluminium {
                                colorOverride 1 1 0.4
                              }
                              geometry Cylinder {
                                height 0.01
                                radius 0.05
                              }
                            }
                          ]
                        }
                        Transform {
                          translation 0.05 0 0.005
                          children [
                            Shape {
                              appearance BrushedAluminium {
                                colorOverride 1 1 0.4
                              }
                              geometry Box {
                                size 0.1 0.1 0.01
                              }
                            }
                          ]
                        }
                        Transform {
                          translation 0.095 0 0.065
                          children [
                            Shape {
                              appearance BrushedAluminium {
                                colorOverride 1 1 0
                              }
                              geometry Box {
                                size 0.01 0.1 0.13
                              }
                            }
                          ]
                        }
                        Transform {
                          translation 0.095 0 0.13
                          rotation 0 1 0 -1.5708
                          children [
                            Shape {
                              appearance BrushedAluminium {
                                colorOverride 1 1 0.4
                              }
                              geometry Cylinder {
                                height 0.01
                                radius 0.05
                              }
                            }
                          ]
                        }
                        Transform {
                          translation 0.09 0 0.13
                          rotation 0 -1 0 1.5707963267948966
                          children [
                            Solid {
                              children [
                                Transform {
                                  translation 0 0 0.05
                                  children [
                                    Shape {
                                      appearance PBRAppearance {
                                        baseColor 1 0 0
                                      }
                                      geometry Box {
                                        size 0.1 0.1 0.1
                                      }
                                    }
                                  ]
                                }
                                Transform {
                                  translation 0 0.055 0.05
                                  rotation -1 0 0 1.5707963267948966
                                  children [
                                    Shape {
                                      geometry Cylinder {
                                        height 0.01
                                        radius 0.02
                                      }
                                    }
                                  ]
                                }
                                Camera {
                                  translation 0 0.06 0.05
                                  rotation 0 0 1 1.5707963267948966
                                  width 96
                                }
                              ]
                              name "output"
                            }
                          ]
                        }
                      ]
                      name "link2"
                    }
                  }
                ]
              }
            ]
            name "link1"
          }
        }
      ]
    }
  ]
  controller "movejoints"
}
FifaSoccerBall {
  translation -0.4 0.4 0.112289
}
Apple {
  translation 0.3 0.4 0.05
}
FlowerPot {
  translation 0.4 0.3 0
}
